[2022-09-22 07:42:47,261] {taskinstance.py:851} INFO - Dependencies all met for <TaskInstance: postgresoperator_demo.create_table_task 2022-09-22T07:42:45.580372+00:00 [queued]>
[2022-09-22 07:42:47,327] {taskinstance.py:851} INFO - Dependencies all met for <TaskInstance: postgresoperator_demo.create_table_task 2022-09-22T07:42:45.580372+00:00 [queued]>
[2022-09-22 07:42:47,327] {taskinstance.py:1042} INFO - 
--------------------------------------------------------------------------------
[2022-09-22 07:42:47,328] {taskinstance.py:1043} INFO - Starting attempt 1 of 1
[2022-09-22 07:42:47,328] {taskinstance.py:1044} INFO - 
--------------------------------------------------------------------------------
[2022-09-22 07:42:47,365] {taskinstance.py:1063} INFO - Executing <Task(PostgresOperator): create_table_task> on 2022-09-22T07:42:45.580372+00:00
[2022-09-22 07:42:47,391] {standard_task_runner.py:76} INFO - Running: ['airflow', 'tasks', 'run', 'postgresoperator_demo', 'create_table_task', '2022-09-22T07:42:45.580372+00:00', '--job-id', '4', '--pool', 'default_pool', '--raw', '--subdir', 'DAGS_FOLDER/postgresoperator_demo.py', '--cfg-path', '/tmp/tmpx7g3_yje', '--error-file', '/tmp/tmpxsxmpkab']
[2022-09-22 07:42:47,396] {standard_task_runner.py:77} INFO - Job 4: Subtask create_table_task
[2022-09-22 07:42:47,382] {standard_task_runner.py:52} INFO - Started process 43 to run task
[2022-09-22 07:42:47,575] {logging_mixin.py:104} INFO - Running <TaskInstance: postgresoperator_demo.create_table_task 2022-09-22T07:42:45.580372+00:00 [running]> on host e3f1499c8ba5
[2022-09-22 07:42:47,840] {taskinstance.py:1257} INFO - Exporting the following env vars:
AIRFLOW_CTX_DAG_OWNER=airflow
AIRFLOW_CTX_DAG_ID=postgresoperator_demo
AIRFLOW_CTX_TASK_ID=create_table_task
AIRFLOW_CTX_EXECUTION_DATE=2022-09-22T07:42:45.580372+00:00
AIRFLOW_CTX_DAG_RUN_ID=manual__2022-09-22T07:42:45.580372+00:00
[2022-09-22 07:42:47,842] {postgres.py:69} INFO - Executing:  
CREATE TABLE employee (id INT NOT NULL, name VARCHAR(250) NOT NULL, dept VARCHAR(250) NOT NULL);
[2022-09-22 07:42:47,962] {base.py:74} INFO - Using connection to: id: postgres_local. Host: localhost, Port: 8080, Schema: , Login: postgres, Password: XXXXXXXX, extra: None
[2022-09-22 07:42:47,972] {taskinstance.py:1455} ERROR - could not connect to server: Connection refused
	Is the server running on host "localhost" (127.0.0.1) and accepting
	TCP/IP connections on port 8080?
could not connect to server: Cannot assign requested address
	Is the server running on host "localhost" (::1) and accepting
	TCP/IP connections on port 8080?
Traceback (most recent call last):
  File "/home/airflow/.local/lib/python3.6/site-packages/airflow/models/taskinstance.py", line 1112, in _run_raw_task
    self._prepare_and_execute_task_with_callbacks(context, task)
  File "/home/airflow/.local/lib/python3.6/site-packages/airflow/models/taskinstance.py", line 1285, in _prepare_and_execute_task_with_callbacks
    result = self._execute_task(context, task_copy)
  File "/home/airflow/.local/lib/python3.6/site-packages/airflow/models/taskinstance.py", line 1315, in _execute_task
    result = task_copy.execute(context=context)
  File "/home/airflow/.local/lib/python3.6/site-packages/airflow/providers/postgres/operators/postgres.py", line 71, in execute
    self.hook.run(self.sql, self.autocommit, parameters=self.parameters)
  File "/home/airflow/.local/lib/python3.6/site-packages/airflow/hooks/dbapi.py", line 173, in run
    with closing(self.get_conn()) as conn:
  File "/home/airflow/.local/lib/python3.6/site-packages/airflow/providers/postgres/hooks/postgres.py", line 108, in get_conn
    self.conn = psycopg2.connect(**conn_args)
  File "/home/airflow/.local/lib/python3.6/site-packages/psycopg2/__init__.py", line 127, in connect
    conn = _connect(dsn, connection_factory=connection_factory, **kwasync)
psycopg2.OperationalError: could not connect to server: Connection refused
	Is the server running on host "localhost" (127.0.0.1) and accepting
	TCP/IP connections on port 8080?
could not connect to server: Cannot assign requested address
	Is the server running on host "localhost" (::1) and accepting
	TCP/IP connections on port 8080?

[2022-09-22 07:42:47,990] {taskinstance.py:1503} INFO - Marking task as FAILED. dag_id=postgresoperator_demo, task_id=create_table_task, execution_date=20220922T074245, start_date=20220922T074247, end_date=20220922T074247
[2022-09-22 07:42:48,394] {local_task_job.py:146} INFO - Task exited with return code 1
